2025-08-12 23:20:16,451 - error_handlers - INFO - Error handlers configured successfully
2025-08-12 23:20:21,337 - error_handlers - INFO - Error handlers configured successfully
2025-08-12 23:31:57,654 - error_handlers - INFO - Error handlers configured successfully
2025-08-12 23:33:20,477 - middleware - INFO - Request: OPTIONS /me from 127.0.0.1
2025-08-12 23:33:20,479 - middleware - INFO - Response: OPTIONS /me - Status: 405 - Time: 0.002s
2025-08-12 23:33:38,147 - middleware - INFO - Request: POST /login from 127.0.0.1
2025-08-12 23:33:38,382 - error_handlers - ERROR - Application Error: {
  "timestamp": "2025-08-12T18:03:38.226390",
  "error_type": "AppError",
  "error_message": "Invalid credentials",
  "traceback": "Traceback (most recent call last):\n  File \"C:\\msys64\\ucrt64\\lib\\python3.11\\site-packages\\starlette\\_exception_handler.py\", line 42, in wrapped_app\n    await app(scope, receive, sender)\n  File \"C:\\msys64\\ucrt64\\lib\\python3.11\\site-packages\\starlette\\routing.py\", line 73, in app\n    response = await f(request)\n               ^^^^^^^^^^^^^^^^\n  File \"C:\\msys64\\ucrt64\\lib\\python3.11\\site-packages\\fastapi\\routing.py\", line 301, in app\n    raw_response = await run_endpoint_function(\n                   ^^^^^^^^^^^^^^^^^^^^^^^^^^^^\n  File \"C:\\msys64\\ucrt64\\lib\\python3.11\\site-packages\\fastapi\\routing.py\", line 214, in run_endpoint_function\n    return await run_in_threadpool(dependant.call, **values)\n           ^^^^^^^^^^^^^^^^^^^^^^^^^^^^^^^^^^^^^^^^^^^^^^^^^\n  File \"C:\\msys64\\ucrt64\\lib\\python3.11\\site-packages\\starlette\\concurrency.py\", line 37, in run_in_threadpool\n    return await anyio.to_thread.run_sync(func)\n           ^^^^^^^^^^^^^^^^^^^^^^^^^^^^^^^^^^^^\n  File \"C:\\msys64\\ucrt64\\lib\\python3.11\\site-packages\\anyio\\to_thread.py\", line 56, in run_sync\n    return await get_async_backend().run_sync_in_worker_thread(\n           ^^^^^^^^^^^^^^^^^^^^^^^^^^^^^^^^^^^^^^^^^^^^^^^^^^^^\n  File \"C:\\msys64\\ucrt64\\lib\\python3.11\\site-packages\\anyio\\_backends\\_asyncio.py\", line 2470, in run_sync_in_worker_thread\n    return await future\n           ^^^^^^^^^^^^\n  File \"C:\\msys64\\ucrt64\\lib\\python3.11\\site-packages\\anyio\\_backends\\_asyncio.py\", line 967, in run\n    result = context.run(func, *args)\n             ^^^^^^^^^^^^^^^^^^^^^^^^\n  File \"C:\\MAIN-PROJECT\\health-data-exchange\\backend\\main.py\", line 141, in login_org\n    raise HTTPException(\nfastapi.exceptions.HTTPException: 401: Invalid credentials\n",
  "user_id": null,
  "request_path": "/login",
  "request_method": "POST",
  "client_ip": "127.0.0.1",
  "user_agent": "Mozilla/5.0 (Windows NT 10.0; Win64; x64) AppleWebKit/537.36 (KHTML, like Gecko) Chrome/139.0.0.0 Safari/537.36 Edg/139.0.0.0"
}
2025-08-12 23:33:38,384 - middleware - INFO - Response: POST /login - Status: 401 - Time: 0.237s
2025-08-12 23:33:42,286 - middleware - INFO - Request: POST /login from 127.0.0.1
2025-08-12 23:33:42,299 - error_handlers - ERROR - Application Error: {
  "timestamp": "2025-08-12T18:03:42.297913",
  "error_type": "AppError",
  "error_message": "Invalid credentials",
  "traceback": "Traceback (most recent call last):\n  File \"C:\\msys64\\ucrt64\\lib\\python3.11\\site-packages\\starlette\\_exception_handler.py\", line 42, in wrapped_app\n    await app(scope, receive, sender)\n  File \"C:\\msys64\\ucrt64\\lib\\python3.11\\site-packages\\starlette\\routing.py\", line 73, in app\n    response = await f(request)\n               ^^^^^^^^^^^^^^^^\n  File \"C:\\msys64\\ucrt64\\lib\\python3.11\\site-packages\\fastapi\\routing.py\", line 301, in app\n    raw_response = await run_endpoint_function(\n                   ^^^^^^^^^^^^^^^^^^^^^^^^^^^^\n  File \"C:\\msys64\\ucrt64\\lib\\python3.11\\site-packages\\fastapi\\routing.py\", line 214, in run_endpoint_function\n    return await run_in_threadpool(dependant.call, **values)\n           ^^^^^^^^^^^^^^^^^^^^^^^^^^^^^^^^^^^^^^^^^^^^^^^^^\n  File \"C:\\msys64\\ucrt64\\lib\\python3.11\\site-packages\\starlette\\concurrency.py\", line 37, in run_in_threadpool\n    return await anyio.to_thread.run_sync(func)\n           ^^^^^^^^^^^^^^^^^^^^^^^^^^^^^^^^^^^^\n  File \"C:\\msys64\\ucrt64\\lib\\python3.11\\site-packages\\anyio\\to_thread.py\", line 56, in run_sync\n    return await get_async_backend().run_sync_in_worker_thread(\n           ^^^^^^^^^^^^^^^^^^^^^^^^^^^^^^^^^^^^^^^^^^^^^^^^^^^^\n  File \"C:\\msys64\\ucrt64\\lib\\python3.11\\site-packages\\anyio\\_backends\\_asyncio.py\", line 2470, in run_sync_in_worker_thread\n    return await future\n           ^^^^^^^^^^^^\n  File \"C:\\msys64\\ucrt64\\lib\\python3.11\\site-packages\\anyio\\_backends\\_asyncio.py\", line 967, in run\n    result = context.run(func, *args)\n             ^^^^^^^^^^^^^^^^^^^^^^^^\n  File \"C:\\MAIN-PROJECT\\health-data-exchange\\backend\\main.py\", line 141, in login_org\n    raise HTTPException(\nfastapi.exceptions.HTTPException: 401: Invalid credentials\n",
  "user_id": null,
  "request_path": "/login",
  "request_method": "POST",
  "client_ip": "127.0.0.1",
  "user_agent": "Mozilla/5.0 (Windows NT 10.0; Win64; x64) AppleWebKit/537.36 (KHTML, like Gecko) Chrome/139.0.0.0 Safari/537.36 Edg/139.0.0.0"
}
2025-08-12 23:33:42,299 - middleware - INFO - Response: POST /login - Status: 401 - Time: 0.013s
2025-08-12 23:36:41,395 - middleware - INFO - Request: POST /register from 127.0.0.1
2025-08-12 23:36:41,497 - middleware - INFO - Response: POST /register - Status: 200 - Time: 0.102s
2025-08-12 23:36:41,504 - middleware - INFO - Request: POST /login from 127.0.0.1
2025-08-12 23:36:41,590 - middleware - INFO - Response: POST /login - Status: 200 - Time: 0.086s
2025-08-12 23:36:41,596 - middleware - INFO - Request: OPTIONS /me from 127.0.0.1
2025-08-12 23:36:41,597 - middleware - INFO - Response: OPTIONS /me - Status: 405 - Time: 0.001s
2025-08-12 23:36:59,371 - middleware - INFO - Request: POST /register from 127.0.0.1
2025-08-12 23:36:59,383 - error_handlers - ERROR - Application Error: {
  "timestamp": "2025-08-12T18:06:59.378009",
  "error_type": "AppError",
  "error_message": "Email already registered",
  "traceback": "Traceback (most recent call last):\n  File \"C:\\msys64\\ucrt64\\lib\\python3.11\\site-packages\\starlette\\_exception_handler.py\", line 42, in wrapped_app\n    await app(scope, receive, sender)\n  File \"C:\\msys64\\ucrt64\\lib\\python3.11\\site-packages\\starlette\\routing.py\", line 73, in app\n    response = await f(request)\n               ^^^^^^^^^^^^^^^^\n  File \"C:\\msys64\\ucrt64\\lib\\python3.11\\site-packages\\fastapi\\routing.py\", line 301, in app\n    raw_response = await run_endpoint_function(\n                   ^^^^^^^^^^^^^^^^^^^^^^^^^^^^\n  File \"C:\\msys64\\ucrt64\\lib\\python3.11\\site-packages\\fastapi\\routing.py\", line 214, in run_endpoint_function\n    return await run_in_threadpool(dependant.call, **values)\n           ^^^^^^^^^^^^^^^^^^^^^^^^^^^^^^^^^^^^^^^^^^^^^^^^^\n  File \"C:\\msys64\\ucrt64\\lib\\python3.11\\site-packages\\starlette\\concurrency.py\", line 37, in run_in_threadpool\n    return await anyio.to_thread.run_sync(func)\n           ^^^^^^^^^^^^^^^^^^^^^^^^^^^^^^^^^^^^\n  File \"C:\\msys64\\ucrt64\\lib\\python3.11\\site-packages\\anyio\\to_thread.py\", line 56, in run_sync\n    return await get_async_backend().run_sync_in_worker_thread(\n           ^^^^^^^^^^^^^^^^^^^^^^^^^^^^^^^^^^^^^^^^^^^^^^^^^^^^\n  File \"C:\\msys64\\ucrt64\\lib\\python3.11\\site-packages\\anyio\\_backends\\_asyncio.py\", line 2470, in run_sync_in_worker_thread\n    return await future\n           ^^^^^^^^^^^^\n  File \"C:\\msys64\\ucrt64\\lib\\python3.11\\site-packages\\anyio\\_backends\\_asyncio.py\", line 967, in run\n    result = context.run(func, *args)\n             ^^^^^^^^^^^^^^^^^^^^^^^^\n  File \"C:\\MAIN-PROJECT\\health-data-exchange\\backend\\main.py\", line 105, in register_org\n    raise HTTPException(status_code=400, detail=\"Email already registered\")\nfastapi.exceptions.HTTPException: 400: Email already registered\n",
  "user_id": null,
  "request_path": "/register",
  "request_method": "POST",
  "client_ip": "127.0.0.1",
  "user_agent": "Mozilla/5.0 (Windows NT 10.0; Win64; x64) AppleWebKit/537.36 (KHTML, like Gecko) Chrome/139.0.0.0 Safari/537.36 Edg/139.0.0.0"
}
2025-08-12 23:36:59,386 - middleware - INFO - Response: POST /register - Status: 400 - Time: 0.014s
2025-08-12 23:38:03,618 - error_handlers - INFO - Error handlers configured successfully
2025-08-12 23:38:07,757 - error_handlers - INFO - Error handlers configured successfully
2025-08-12 23:38:20,851 - error_handlers - INFO - Error handlers configured successfully
2025-08-12 23:38:24,733 - error_handlers - INFO - Error handlers configured successfully
2025-08-12 23:38:45,507 - middleware - INFO - Request: POST /register from 127.0.0.1
2025-08-12 23:38:45,570 - error_handlers - ERROR - Application Error: {
  "timestamp": "2025-08-12T18:08:45.567650",
  "error_type": "AppError",
  "error_message": "Email already registered",
  "traceback": "Traceback (most recent call last):\n  File \"C:\\msys64\\ucrt64\\lib\\python3.11\\site-packages\\starlette\\_exception_handler.py\", line 42, in wrapped_app\n    await app(scope, receive, sender)\n  File \"C:\\msys64\\ucrt64\\lib\\python3.11\\site-packages\\starlette\\routing.py\", line 73, in app\n    response = await f(request)\n               ^^^^^^^^^^^^^^^^\n  File \"C:\\msys64\\ucrt64\\lib\\python3.11\\site-packages\\fastapi\\routing.py\", line 301, in app\n    raw_response = await run_endpoint_function(\n                   ^^^^^^^^^^^^^^^^^^^^^^^^^^^^\n  File \"C:\\msys64\\ucrt64\\lib\\python3.11\\site-packages\\fastapi\\routing.py\", line 214, in run_endpoint_function\n    return await run_in_threadpool(dependant.call, **values)\n           ^^^^^^^^^^^^^^^^^^^^^^^^^^^^^^^^^^^^^^^^^^^^^^^^^\n  File \"C:\\msys64\\ucrt64\\lib\\python3.11\\site-packages\\starlette\\concurrency.py\", line 37, in run_in_threadpool\n    return await anyio.to_thread.run_sync(func)\n           ^^^^^^^^^^^^^^^^^^^^^^^^^^^^^^^^^^^^\n  File \"C:\\msys64\\ucrt64\\lib\\python3.11\\site-packages\\anyio\\to_thread.py\", line 56, in run_sync\n    return await get_async_backend().run_sync_in_worker_thread(\n           ^^^^^^^^^^^^^^^^^^^^^^^^^^^^^^^^^^^^^^^^^^^^^^^^^^^^\n  File \"C:\\msys64\\ucrt64\\lib\\python3.11\\site-packages\\anyio\\_backends\\_asyncio.py\", line 2470, in run_sync_in_worker_thread\n    return await future\n           ^^^^^^^^^^^^\n  File \"C:\\msys64\\ucrt64\\lib\\python3.11\\site-packages\\anyio\\_backends\\_asyncio.py\", line 967, in run\n    result = context.run(func, *args)\n             ^^^^^^^^^^^^^^^^^^^^^^^^\n  File \"C:\\MAIN-PROJECT\\health-data-exchange\\backend\\main.py\", line 105, in register_org\n    raise HTTPException(status_code=400, detail=\"Email already registered\")\nfastapi.exceptions.HTTPException: 400: Email already registered\n",
  "user_id": null,
  "request_path": "/register",
  "request_method": "POST",
  "client_ip": "127.0.0.1",
  "user_agent": "Mozilla/5.0 (Windows NT 10.0; Win64; x64) AppleWebKit/537.36 (KHTML, like Gecko) Chrome/139.0.0.0 Safari/537.36 Edg/139.0.0.0"
}
2025-08-12 23:38:45,570 - middleware - INFO - Response: POST /register - Status: 400 - Time: 0.063s
2025-08-12 23:41:05,752 - error_handlers - INFO - Error handlers configured successfully
2025-08-12 23:41:08,528 - middleware - INFO - Request: POST /login from 127.0.0.1
2025-08-12 23:41:08,694 - middleware - INFO - Response: POST /login - Status: 200 - Time: 0.165s
2025-08-12 23:41:08,706 - middleware - INFO - Request: GET /me from 127.0.0.1
2025-08-12 23:41:08,713 - middleware - INFO - Response: GET /me - Status: 200 - Time: 0.007s
2025-08-12 23:41:16,015 - middleware - INFO - Request: GET /uploads from 127.0.0.1
2025-08-12 23:41:16,037 - middleware - INFO - Response: GET /uploads - Status: 200 - Time: 0.020s
2025-08-12 23:41:16,043 - middleware - INFO - Request: GET /uploads from 127.0.0.1
2025-08-12 23:41:16,071 - middleware - INFO - Response: GET /uploads - Status: 200 - Time: 0.028s
2025-08-12 23:41:34,404 - middleware - INFO - Request: POST /login from 127.0.0.1
2025-08-12 23:41:34,516 - error_handlers - ERROR - Application Error: {
  "timestamp": "2025-08-12T18:11:34.511465",
  "error_type": "AppError",
  "error_message": "Invalid credentials",
  "traceback": "Traceback (most recent call last):\n  File \"C:\\msys64\\ucrt64\\lib\\python3.11\\site-packages\\starlette\\_exception_handler.py\", line 42, in wrapped_app\n    await app(scope, receive, sender)\n  File \"C:\\msys64\\ucrt64\\lib\\python3.11\\site-packages\\starlette\\routing.py\", line 73, in app\n    response = await f(request)\n               ^^^^^^^^^^^^^^^^\n  File \"C:\\msys64\\ucrt64\\lib\\python3.11\\site-packages\\fastapi\\routing.py\", line 301, in app\n    raw_response = await run_endpoint_function(\n                   ^^^^^^^^^^^^^^^^^^^^^^^^^^^^\n  File \"C:\\msys64\\ucrt64\\lib\\python3.11\\site-packages\\fastapi\\routing.py\", line 214, in run_endpoint_function\n    return await run_in_threadpool(dependant.call, **values)\n           ^^^^^^^^^^^^^^^^^^^^^^^^^^^^^^^^^^^^^^^^^^^^^^^^^\n  File \"C:\\msys64\\ucrt64\\lib\\python3.11\\site-packages\\starlette\\concurrency.py\", line 37, in run_in_threadpool\n    return await anyio.to_thread.run_sync(func)\n           ^^^^^^^^^^^^^^^^^^^^^^^^^^^^^^^^^^^^\n  File \"C:\\msys64\\ucrt64\\lib\\python3.11\\site-packages\\anyio\\to_thread.py\", line 56, in run_sync\n    return await get_async_backend().run_sync_in_worker_thread(\n           ^^^^^^^^^^^^^^^^^^^^^^^^^^^^^^^^^^^^^^^^^^^^^^^^^^^^\n  File \"C:\\msys64\\ucrt64\\lib\\python3.11\\site-packages\\anyio\\_backends\\_asyncio.py\", line 2470, in run_sync_in_worker_thread\n    return await future\n           ^^^^^^^^^^^^\n  File \"C:\\msys64\\ucrt64\\lib\\python3.11\\site-packages\\anyio\\_backends\\_asyncio.py\", line 967, in run\n    result = context.run(func, *args)\n             ^^^^^^^^^^^^^^^^^^^^^^^^\n  File \"C:\\MAIN-PROJECT\\health-data-exchange\\backend\\main.py\", line 141, in login_org\n    raise HTTPException(\nfastapi.exceptions.HTTPException: 401: Invalid credentials\n",
  "user_id": null,
  "request_path": "/login",
  "request_method": "POST",
  "client_ip": "127.0.0.1",
  "user_agent": "Mozilla/5.0 (Windows NT 10.0; Win64; x64) AppleWebKit/537.36 (KHTML, like Gecko) Chrome/139.0.0.0 Safari/537.36 Edg/139.0.0.0"
}
2025-08-12 23:41:34,516 - middleware - INFO - Response: POST /login - Status: 401 - Time: 0.112s
2025-08-12 23:48:33,144 - error_handlers - INFO - Error handlers configured successfully
2025-08-12 23:51:41,001 - error_handlers - INFO - Error handlers configured successfully
2025-08-12 23:51:43,804 - middleware - INFO - Request: POST /login from 127.0.0.1
2025-08-12 23:51:43,974 - error_handlers - ERROR - Application Error: {
  "timestamp": "2025-08-12T18:21:43.961914",
  "error_type": "AppError",
  "error_message": "Invalid credentials",
  "traceback": "Traceback (most recent call last):\n  File \"C:\\msys64\\ucrt64\\lib\\python3.11\\site-packages\\starlette\\_exception_handler.py\", line 42, in wrapped_app\n    await app(scope, receive, sender)\n  File \"C:\\msys64\\ucrt64\\lib\\python3.11\\site-packages\\starlette\\routing.py\", line 73, in app\n    response = await f(request)\n               ^^^^^^^^^^^^^^^^\n  File \"C:\\msys64\\ucrt64\\lib\\python3.11\\site-packages\\fastapi\\routing.py\", line 301, in app\n    raw_response = await run_endpoint_function(\n                   ^^^^^^^^^^^^^^^^^^^^^^^^^^^^\n  File \"C:\\msys64\\ucrt64\\lib\\python3.11\\site-packages\\fastapi\\routing.py\", line 214, in run_endpoint_function\n    return await run_in_threadpool(dependant.call, **values)\n           ^^^^^^^^^^^^^^^^^^^^^^^^^^^^^^^^^^^^^^^^^^^^^^^^^\n  File \"C:\\msys64\\ucrt64\\lib\\python3.11\\site-packages\\starlette\\concurrency.py\", line 37, in run_in_threadpool\n    return await anyio.to_thread.run_sync(func)\n           ^^^^^^^^^^^^^^^^^^^^^^^^^^^^^^^^^^^^\n  File \"C:\\msys64\\ucrt64\\lib\\python3.11\\site-packages\\anyio\\to_thread.py\", line 56, in run_sync\n    return await get_async_backend().run_sync_in_worker_thread(\n           ^^^^^^^^^^^^^^^^^^^^^^^^^^^^^^^^^^^^^^^^^^^^^^^^^^^^\n  File \"C:\\msys64\\ucrt64\\lib\\python3.11\\site-packages\\anyio\\_backends\\_asyncio.py\", line 2470, in run_sync_in_worker_thread\n    return await future\n           ^^^^^^^^^^^^\n  File \"C:\\msys64\\ucrt64\\lib\\python3.11\\site-packages\\anyio\\_backends\\_asyncio.py\", line 967, in run\n    result = context.run(func, *args)\n             ^^^^^^^^^^^^^^^^^^^^^^^^\n  File \"C:\\MAIN-PROJECT\\health-data-exchange\\backend\\main.py\", line 141, in login_org\n    raise HTTPException(\nfastapi.exceptions.HTTPException: 401: Invalid credentials\n",
  "user_id": null,
  "request_path": "/login",
  "request_method": "POST",
  "client_ip": "127.0.0.1",
  "user_agent": "Mozilla/5.0 (Windows NT 10.0; Win64; x64) AppleWebKit/537.36 (KHTML, like Gecko) Chrome/139.0.0.0 Safari/537.36 Edg/139.0.0.0"
}
2025-08-12 23:51:43,976 - middleware - INFO - Response: POST /login - Status: 401 - Time: 0.172s
2025-08-12 23:51:54,762 - middleware - INFO - Request: POST /login from 127.0.0.1
2025-08-12 23:51:54,869 - error_handlers - ERROR - Application Error: {
  "timestamp": "2025-08-12T18:21:54.867727",
  "error_type": "AppError",
  "error_message": "Invalid credentials",
  "traceback": "Traceback (most recent call last):\n  File \"C:\\msys64\\ucrt64\\lib\\python3.11\\site-packages\\starlette\\_exception_handler.py\", line 42, in wrapped_app\n    await app(scope, receive, sender)\n  File \"C:\\msys64\\ucrt64\\lib\\python3.11\\site-packages\\starlette\\routing.py\", line 73, in app\n    response = await f(request)\n               ^^^^^^^^^^^^^^^^\n  File \"C:\\msys64\\ucrt64\\lib\\python3.11\\site-packages\\fastapi\\routing.py\", line 301, in app\n    raw_response = await run_endpoint_function(\n                   ^^^^^^^^^^^^^^^^^^^^^^^^^^^^\n  File \"C:\\msys64\\ucrt64\\lib\\python3.11\\site-packages\\fastapi\\routing.py\", line 214, in run_endpoint_function\n    return await run_in_threadpool(dependant.call, **values)\n           ^^^^^^^^^^^^^^^^^^^^^^^^^^^^^^^^^^^^^^^^^^^^^^^^^\n  File \"C:\\msys64\\ucrt64\\lib\\python3.11\\site-packages\\starlette\\concurrency.py\", line 37, in run_in_threadpool\n    return await anyio.to_thread.run_sync(func)\n           ^^^^^^^^^^^^^^^^^^^^^^^^^^^^^^^^^^^^\n  File \"C:\\msys64\\ucrt64\\lib\\python3.11\\site-packages\\anyio\\to_thread.py\", line 56, in run_sync\n    return await get_async_backend().run_sync_in_worker_thread(\n           ^^^^^^^^^^^^^^^^^^^^^^^^^^^^^^^^^^^^^^^^^^^^^^^^^^^^\n  File \"C:\\msys64\\ucrt64\\lib\\python3.11\\site-packages\\anyio\\_backends\\_asyncio.py\", line 2470, in run_sync_in_worker_thread\n    return await future\n           ^^^^^^^^^^^^\n  File \"C:\\msys64\\ucrt64\\lib\\python3.11\\site-packages\\anyio\\_backends\\_asyncio.py\", line 967, in run\n    result = context.run(func, *args)\n             ^^^^^^^^^^^^^^^^^^^^^^^^\n  File \"C:\\MAIN-PROJECT\\health-data-exchange\\backend\\main.py\", line 141, in login_org\n    raise HTTPException(\nfastapi.exceptions.HTTPException: 401: Invalid credentials\n",
  "user_id": null,
  "request_path": "/login",
  "request_method": "POST",
  "client_ip": "127.0.0.1",
  "user_agent": "Mozilla/5.0 (Windows NT 10.0; Win64; x64) AppleWebKit/537.36 (KHTML, like Gecko) Chrome/139.0.0.0 Safari/537.36 Edg/139.0.0.0"
}
2025-08-12 23:51:54,870 - middleware - INFO - Response: POST /login - Status: 401 - Time: 0.108s
2025-08-12 23:52:17,963 - middleware - INFO - Request: POST /login from 127.0.0.1
2025-08-12 23:52:18,064 - error_handlers - ERROR - Application Error: {
  "timestamp": "2025-08-12T18:22:18.061759",
  "error_type": "AppError",
  "error_message": "Invalid credentials",
  "traceback": "Traceback (most recent call last):\n  File \"C:\\msys64\\ucrt64\\lib\\python3.11\\site-packages\\starlette\\_exception_handler.py\", line 42, in wrapped_app\n    await app(scope, receive, sender)\n  File \"C:\\msys64\\ucrt64\\lib\\python3.11\\site-packages\\starlette\\routing.py\", line 73, in app\n    response = await f(request)\n               ^^^^^^^^^^^^^^^^\n  File \"C:\\msys64\\ucrt64\\lib\\python3.11\\site-packages\\fastapi\\routing.py\", line 301, in app\n    raw_response = await run_endpoint_function(\n                   ^^^^^^^^^^^^^^^^^^^^^^^^^^^^\n  File \"C:\\msys64\\ucrt64\\lib\\python3.11\\site-packages\\fastapi\\routing.py\", line 214, in run_endpoint_function\n    return await run_in_threadpool(dependant.call, **values)\n           ^^^^^^^^^^^^^^^^^^^^^^^^^^^^^^^^^^^^^^^^^^^^^^^^^\n  File \"C:\\msys64\\ucrt64\\lib\\python3.11\\site-packages\\starlette\\concurrency.py\", line 37, in run_in_threadpool\n    return await anyio.to_thread.run_sync(func)\n           ^^^^^^^^^^^^^^^^^^^^^^^^^^^^^^^^^^^^\n  File \"C:\\msys64\\ucrt64\\lib\\python3.11\\site-packages\\anyio\\to_thread.py\", line 56, in run_sync\n    return await get_async_backend().run_sync_in_worker_thread(\n           ^^^^^^^^^^^^^^^^^^^^^^^^^^^^^^^^^^^^^^^^^^^^^^^^^^^^\n  File \"C:\\msys64\\ucrt64\\lib\\python3.11\\site-packages\\anyio\\_backends\\_asyncio.py\", line 2470, in run_sync_in_worker_thread\n    return await future\n           ^^^^^^^^^^^^\n  File \"C:\\msys64\\ucrt64\\lib\\python3.11\\site-packages\\anyio\\_backends\\_asyncio.py\", line 967, in run\n    result = context.run(func, *args)\n             ^^^^^^^^^^^^^^^^^^^^^^^^\n  File \"C:\\MAIN-PROJECT\\health-data-exchange\\backend\\main.py\", line 141, in login_org\n    raise HTTPException(\nfastapi.exceptions.HTTPException: 401: Invalid credentials\n",
  "user_id": null,
  "request_path": "/login",
  "request_method": "POST",
  "client_ip": "127.0.0.1",
  "user_agent": "Mozilla/5.0 (Windows NT 10.0; Win64; x64) AppleWebKit/537.36 (KHTML, like Gecko) Chrome/139.0.0.0 Safari/537.36 Edg/139.0.0.0"
}
2025-08-12 23:52:18,066 - middleware - INFO - Response: POST /login - Status: 401 - Time: 0.104s
2025-08-12 23:52:26,659 - middleware - INFO - Request: POST /login from 127.0.0.1
2025-08-12 23:52:26,759 - middleware - INFO - Response: POST /login - Status: 200 - Time: 0.100s
2025-08-12 23:52:26,772 - middleware - INFO - Request: GET /me from 127.0.0.1
2025-08-12 23:52:26,780 - middleware - INFO - Response: GET /me - Status: 200 - Time: 0.008s
2025-08-12 23:52:26,914 - middleware - INFO - Request: GET /uploads from 127.0.0.1
2025-08-12 23:52:26,938 - middleware - INFO - Response: GET /uploads - Status: 200 - Time: 0.024s
2025-08-12 23:52:26,944 - middleware - INFO - Request: GET /uploads from 127.0.0.1
2025-08-12 23:52:26,958 - middleware - INFO - Response: GET /uploads - Status: 200 - Time: 0.014s
2025-08-12 23:53:44,794 - middleware - INFO - Request: POST /register from 127.0.0.1
2025-08-12 23:53:44,908 - middleware - INFO - Response: POST /register - Status: 200 - Time: 0.115s
2025-08-12 23:53:44,915 - middleware - INFO - Request: POST /login from 127.0.0.1
2025-08-12 23:53:45,019 - middleware - INFO - Response: POST /login - Status: 200 - Time: 0.104s
2025-08-12 23:53:45,029 - middleware - INFO - Request: GET /me from 127.0.0.1
2025-08-12 23:53:45,035 - middleware - INFO - Response: GET /me - Status: 200 - Time: 0.006s
2025-08-12 23:55:16,154 - error_handlers - INFO - Error handlers configured successfully
2025-08-12 23:55:26,578 - error_handlers - INFO - Error handlers configured successfully
2025-08-12 23:55:37,681 - middleware - INFO - Request: POST /register from 127.0.0.1
2025-08-12 23:55:37,735 - error_handlers - ERROR - Application Error: {
  "timestamp": "2025-08-12T18:25:37.728498",
  "error_type": "AppError",
  "error_message": "Email already registered",
  "traceback": "Traceback (most recent call last):\n  File \"C:\\msys64\\ucrt64\\lib\\python3.11\\site-packages\\starlette\\_exception_handler.py\", line 42, in wrapped_app\n    await app(scope, receive, sender)\n  File \"C:\\msys64\\ucrt64\\lib\\python3.11\\site-packages\\starlette\\routing.py\", line 73, in app\n    response = await f(request)\n               ^^^^^^^^^^^^^^^^\n  File \"C:\\msys64\\ucrt64\\lib\\python3.11\\site-packages\\fastapi\\routing.py\", line 301, in app\n    raw_response = await run_endpoint_function(\n                   ^^^^^^^^^^^^^^^^^^^^^^^^^^^^\n  File \"C:\\msys64\\ucrt64\\lib\\python3.11\\site-packages\\fastapi\\routing.py\", line 214, in run_endpoint_function\n    return await run_in_threadpool(dependant.call, **values)\n           ^^^^^^^^^^^^^^^^^^^^^^^^^^^^^^^^^^^^^^^^^^^^^^^^^\n  File \"C:\\msys64\\ucrt64\\lib\\python3.11\\site-packages\\starlette\\concurrency.py\", line 37, in run_in_threadpool\n    return await anyio.to_thread.run_sync(func)\n           ^^^^^^^^^^^^^^^^^^^^^^^^^^^^^^^^^^^^\n  File \"C:\\msys64\\ucrt64\\lib\\python3.11\\site-packages\\anyio\\to_thread.py\", line 56, in run_sync\n    return await get_async_backend().run_sync_in_worker_thread(\n           ^^^^^^^^^^^^^^^^^^^^^^^^^^^^^^^^^^^^^^^^^^^^^^^^^^^^\n  File \"C:\\msys64\\ucrt64\\lib\\python3.11\\site-packages\\anyio\\_backends\\_asyncio.py\", line 2470, in run_sync_in_worker_thread\n    return await future\n           ^^^^^^^^^^^^\n  File \"C:\\msys64\\ucrt64\\lib\\python3.11\\site-packages\\anyio\\_backends\\_asyncio.py\", line 967, in run\n    result = context.run(func, *args)\n             ^^^^^^^^^^^^^^^^^^^^^^^^\n  File \"C:\\MAIN-PROJECT\\health-data-exchange\\backend\\main.py\", line 105, in register_org\n    raise HTTPException(status_code=400, detail=\"Email already registered\")\nfastapi.exceptions.HTTPException: 400: Email already registered\n",
  "user_id": null,
  "request_path": "/register",
  "request_method": "POST",
  "client_ip": "127.0.0.1",
  "user_agent": "Mozilla/5.0 (Windows NT 10.0; Win64; x64) AppleWebKit/537.36 (KHTML, like Gecko) Chrome/139.0.0.0 Safari/537.36 Edg/139.0.0.0"
}
2025-08-12 23:55:37,737 - middleware - INFO - Response: POST /register - Status: 400 - Time: 0.056s
